Workbook
Name LISTA_TIPOS_2P: VALIDACIONES!$A$1:$A$8
Name RESP_VF: VALIDACIONES!$B$1:$B$2
Name RESP_ABCD: VALIDACIONES!$C$1:$C$4
Name RESP_ABCDE: VALIDACIONES!$D$1:$D$5
Name RESP_VACIA: VALIDACIONES!$E$1
Name DIFICULTADES_123: VALIDACIONES!$F$1:$F$3
Name PARCIAL_ACTIVO_BANCO: VALIDACIONES!$G$1
Name RESP_CLAVE: VALIDACIONES!$H$1:$H$5
Name MAPA_RESPUESTA_TIPO: VALIDACIONES!$J$1:$K$6
Name TIPOS_REQUIEREN_GRUPO: VALIDACIONES!$L$1:$L$4
Name TIPOS_SIN_DIFICULTAD: VALIDACIONES!$M$1:$M$2
Name TIPOS_OPCION_D: VALIDACIONES!$N$1:$N$6
Name TIPOS_OPCION_E: VALIDACIONES!$O$1:$O$6
Name TIPOS_OPCION_F: VALIDACIONES!$P$1:$P$5
Name TIPOS_OPCION_G: VALIDACIONES!$Q$1:$Q$5
Name TIPOS_OPCION_H: VALIDACIONES!$R$1:$R$3

Sheet Instrucciones
A1: BANCO DE PREGUNTAS - GUIA OFICIAL
A3: 1. CODIGOS DE PREGUNTA (Columna TIPO)
A4: Verdadero o Falso Simple | B4: Se completan automáticamente opcion_a=Verdadero y opcion_b=Falso. Deje opcion_c, opcion_d y opcion_e vacías.
A5: Verdadero o Falso Complejas | B5: Escriba las premisas 1-4 en opcion_a a opcion_d. opcion_e se completa vacía; respuesta_correcta puede ser A, B, C, D o E según la combinación de premisas.
A6: Selección de la mejor respuesta | B6: Complete las cinco alternativas en opcion_a a opcion_e y marque una sola letra en respuesta_correcta.
A7: Respuesta A/B/Ambas/Ninguna | B7: Se completan automáticamente las opciones A-D. opcion_e debe permanecer vacía y respuesta_correcta debe ser A, B, C o D.
A8: Ítems agrupados por caso clínico o problema | B8: Solo complete grupo y enunciado. Este tronco no lleva opciones, dificultad ni respuesta_correcta.
A9: Subítem de caso o problema | B9: Complete grupo, enunciado, las cinco alternativas y respuesta_correcta. El subítem sí lleva dificultad.
A10: Emparejamiento Ampliado | B10: Complete grupo y enunciado con las claves de emparejamiento. Este tronco no lleva dificultad ni respuesta_correcta.
A11: Opción de Emparejamiento Ampliado | B11: Complete grupo, enunciado y respuesta_correcta. No lleva opciones en columnas ni dificultad.
A13: 2. RESPUESTAS VALIDAS
A14: Verdadero o Falso Complejas | B14: Use una de las combinaciones fijas: A: 1, 2, 3 correctas; B: 1 y 3 correctas; C: 2 y 4 correctas; D: Solo 4 es correcta; E: Todas son correctas.
A15: Selección de la mejor respuesta / Subítem de caso o problema | B15: Use una sola letra: A, B, C, D o E.
A16: Emparejamiento Ampliado / Ítems agrupados por caso clínico o problema | B16: Deje respuesta_correcta vacia.
A17: Respuesta A/B/Ambas/Ninguna | B17: La respuesta_correcta solo puede ser A, B, C o D.
A18: Verdadero o Falso Simple | B18: A para Verdadero, B para Falso.
A19: Opción de Emparejamiento Ampliado | B19: Use la letra correcta segun las opciones activas definidas en el encabezado del emparejamiento.
A20: Ítems agrupados por caso clínico o problema | B20: No debe llevar respuesta_correcta.
A22: 3. CONFIGURACION DEL EXAMEN
A23: Dificultad (Nivel) | B23: 1 (Facil), 2 (Medio), 3 (Dificil). Casos/problemas y Emparejamiento Ampliado no llevan dificultad.
A24: Parcial activo | B24: 2P (2do Parcial)
A25: Registro por grupo | B25: En el 2do Parcial el banco se organiza y se valida individualmente por grupo teorico.
A26: Columna observaciones | B26: La columna L se completa automaticamente y te dira si la fila esta OK o que campos faltan/revisar.
A27: M (imagen_base64) | B27: Imagen opcional. Puede incluir #sea-size=GRANDE, MEDIANA, PEQUENA o MUY_PEQUENA; MEDIANA es el tamaño predeterminado.
A28: NOTAS IMPORTANTES
A29: - No elimine columnas ni cambie el nombre de la hoja "Banco".
A30: - IMPORTANTE: Respuesta A/B/Ambas/Ninguna usa solo las premisas I. y II. en enunciado; opcion_a a opcion_d lleva las respuestas fijas y opcion_e no se usa.
A31: - IMPORTANTE: Verdadero o Falso Complejas usa los incisos 1, 2, 3 y 4 en opcion_a a opcion_d. opcion_e debe quedar vacia; respuesta_correcta puede ser A, B, C, D o E, porque E representa una combinacion.
A32: - IMPORTANTE: Casos/problemas y Emparejamiento Ampliado son encabezados y no deben tener dificultad.
A33: - IMPORTANTE: Si la columna L no indica "OK", corrige esa fila antes de importar.
A34: - Conteo por grupos de tipo: Grupo 1 = VF simple + VF complejas + A/B/Ambas/Ninguna. Grupo 2 = mejor respuesta. Grupo 3 = casos/problemas y emparejamiento ampliado.
A35: AYUDA RÁPIDA PARA INCISOS
A36: Verdadero o Falso Simple | B36: A=Verdadero y B=Falso se completan automáticamente; deje C-E vacíos.
A37: Respuesta A/B/Ambas/Ninguna | B37: A-D se completan automáticamente; deje E vacío.
A38: Verdadero o Falso Complejas | B38: Escriba las premisas 1-4 en A-D; E vacío. La respuesta correcta puede ser A-E por las combinaciones.
A39: Selección de la mejor respuesta | B39: Complete las cinco alternativas A-E y luego indique una sola letra como respuesta correcta.
A40: Subítem de caso o problema | B40: Complete las cinco alternativas A-E, respuesta_correcta y dificultad.

Sheet Banco
A1: tipo | B1: grupo | C1: enunciado | D1: opcion_a | E1: opcion_b | F1: opcion_c | G1: opcion_d | H1: opcion_e | I1: respuesta_correcta | J1: dificultad | K1: parcial | L1: observaciones | M1: imagen_base64 | Q1: _obs_1 | R1: _obs_2 | S1: _obs_3 | T1: _obs_4 | U1: _obs_1 | V1: _obs_2 | W1: _obs_3 | X1: _obs_4 | Y1: _obs_1 | Z1: _obs_2 | AA1: _obs_3 | AB1: _obs_4 | AC1: _obs_1 | AD1: _obs_2 | AE1: _obs_3 | AF1: _obs_4 | AG1: _obs_1 | AH1: _obs_2 | AI1: _obs_3 | AJ1: _obs_4 | AK1: _obs_1 | AL1: _obs_2 | AM1: _obs_3 | AN1: _obs_4 | AO1: CONTROL DE DISTRIBUCIÓN – 2P
D2: =IF($A2="Verdadero o Falso Simple","Verdadero",IF($A2="Respuesta A/B/Ambas/Ninguna","A. Si la primera es verdadera",IF($A2="Verdadero o Falso Complejas","1. ",""))) | E2: =IF($A2="Verdadero o Falso Simple","Falso",IF($A2="Respuesta A/B/Ambas/Ninguna","B. Si la segunda es verdadera",IF($A2="Verdadero o Falso Complejas","2. ",""))) | F2: =IF($A2="Respuesta A/B/Ambas/Ninguna","C. Si ambas son verdaderas",IF($A2="Verdadero o Falso Complejas","3. ","")) | G2: =IF($A2="Respuesta A/B/Ambas/Ninguna","D. Si ninguna es verdadera",IF($A2="Verdadero o Falso Complejas","4. ","")) | H2: =IF($A2="Verdadero o Falso Simple","",IF($A2="Respuesta A/B/Ambas/Ninguna","",IF($A2="Verdadero o Falso Complejas","",""))) | J2: 1 | K2: 2P | L2: =IF(TRIM($A2)="","",IF(OR($A2="Selección de la mejor respuesta",$A2="SELECCION_MEJOR_RESPUESTA",$A2="Subítem de caso o problema",$A2="SUBITEM_CASO"),IF(TRIM($C2)="","Completar enunciado",IF(SUMPRODUCT(--(LEN(TRIM($D2:$H2&""))>0))<5,"Completar opciones A-E",IF(AND(TRIM($I2)<>"",OR(LEFT(TRIM($I2),1)="A",LEFT(TRIM($I2),1)="B",LEFT(TRIM($I2),1)="C",LEFT(TRIM($I2),1)="D",LEFT(TRIM($I2),1)="E")),"OK","Completar respuesta correcta A-E"))),IF(TRIM($A2)="","",IF(COUNTIF($Q2:$AJ2,"?*")=0,"OK","Falta revisar: "&$Q2&$R2&$S2&$T2&$U2&$V2&$W2&$X2&$Y2&$Z2&$AA2&$AB2&$AC2&$AD2&$AE2&$AF2&$AG2&$AH2&$AI2&$AJ2)))) | Q2: =IF(TRIM($C2)="","enunciado","") | R2: =IF(TRIM($K2)="",IF(COUNTIF($Q2:$Q2,"?*")>0,", ","")&"parcial","") | S2: =IF(AND(TRIM($K2)<>"",TRIM($K2)<>VALIDACIONES!$G$1),IF(COUNTIF($Q2:$R2,"?*")>0,", ","")&"parcial distinto a "&VALIDACIONES!$G$1,"") | T2: =IF(AND(OR($A2="Ítems agrupados por caso clínico o problema",$A2="Subítem de caso o problema",$A2="Emparejamiento Ampliado",$A2="Opción de Emparejamiento Ampliado"),TRIM($B2)=""),IF(COUNTIF($Q2:$S2,"?*")>0,", ","")&"grupo","") | U2: =IF(AND(OR($A2="Verdadero o Falso Simple",$A2="Respuesta A/B/Ambas/Ninguna",$A2="Verdadero o Falso Complejas",$A2="Selección de la mejor respuesta",$A2="Subítem de caso o problema",$A2="Opción de Emparejamiento Ampliado"),TRIM($I2)=""),IF(COUNTIF($Q2:$T2,"?*")>0,", ","")&"respuesta_correcta","") | V2: =IF(AND(OR($A2="Verdadero o Falso Simple",$A2="Respuesta A/B/Ambas/Ninguna",$A2="Verdadero o Falso Complejas",$A2="Selección de la mejor respuesta",$A2="Subítem de caso o problema",$A2="Opción de Emparejamiento Ampliado"),TRIM($J2)=""),IF(COUNTIF($Q2:$U2,"?*")>0,", ","")&"dificultad","") | W2: =IF(AND(OR($A2="Ítems agrupados por caso clínico o problema",$A2="Emparejamiento Ampliado"),TRIM($I2)<>""),IF(COUNTIF($Q2:$V2,"?*")>0,", ","")&"respuesta debe ir vacia","") | X2: =IF(AND(OR($A2="Ítems agrupados por caso clínico o problema",$A2="Emparejamiento Ampliado"),TRIM($J2)<>""),IF(COUNTIF($Q2:$W2,"?*")>0,", ","")&"dificultad debe ir vacia","") | Y2: =IF(AND($A2="Verdadero o Falso Simple",OR(COUNTIF($D2:$E2,"?*")<2,COUNTIF($F2:$H2,"?*")>0)),IF(COUNTIF($Q2:$X2,"?*")>0,", ","")&"incisos A-B","") | Z2: =IF(AND($A2="Verdadero o Falso Simple",TRIM($I2)<>"",NOT(OR(LEFT(TRIM($I2),1)="A",LEFT(TRIM($I2),1)="B"))),IF(COUNTIF($Q2:$Y2,"?*")>0,", ","")&"respuesta A-B","") | AA2: =IF(AND($A2="Respuesta A/B/Ambas/Ninguna",COUNTIF($D2:$G2,"?*")<4),IF(COUNTIF($Q2:$Z2,"?*")>0,", ","")&"opciones A-D","") | AB2: =IF(AND($A2="Respuesta A/B/Ambas/Ninguna",COUNTIF($H2:$H2,"?*")>0),IF(COUNTIF($Q2:$AA2,"?*")>0,", ","")&"opcion E deshabilitada","") | AC2: =IF(AND($A2="Respuesta A/B/Ambas/Ninguna",TRIM($I2)<>"",NOT(OR(LEFT(TRIM($I2),1)="A",LEFT(TRIM($I2),1)="B",LEFT(TRIM($I2),1)="C",LEFT(TRIM($I2),1)="D"))),IF(COUNTIF($Q2:$AB2,"?*")>0,", ","")&"respuesta A-D","") | AD2: =IF(AND($A2="Verdadero o Falso Complejas",OR(LEN(TRIM(SUBSTITUTE($D2,"1.","")))=0,LEN(TRIM(SUBSTITUTE($E2,"2.","")))=0,LEN(TRIM(SUBSTITUTE($F2,"3.","")))=0,LEN(TRIM(SUBSTITUTE($G2,"4.","")))=0)),IF(COUNTIF($Q2:$AC2,"?*")>0,", ","")&"incisos 1-4","") | AE2: =IF(AND($A2="Verdadero o Falso Complejas",COUNTIF($H2:$H2,"?*")>0),IF(COUNTIF($Q2:$AD2,"?*")>0,", ","")&"opcion E deshabilitada","") | AF2: =IF(AND($A2="Verdadero o Falso Complejas",TRIM($I2)<>"",NOT(OR(LEFT(TRIM($I2),1)="A",LEFT(TRIM($I2),1)="B",LEFT(TRIM($I2),1)="C",LEFT(TRIM($I2),1)="D",LEFT(TRIM($I2),1)="E"))),IF(COUNTIF($Q2:$AE2,"?*")>0,", ","")&"respuesta A-E","") | AG2: =IF(AND(OR($A2="Selección de la mejor respuesta",$A2="Subítem de caso o problema"),COUNTA($D2:$H2)<5),IF(COUNTIF($Q2:$AF2,"?*")>0,", ","")&"incisos A-E","") | AH2: =IF(AND(OR($A2="Selección de la mejor respuesta",$A2="Subítem de caso o problema"),TRIM($I2)<>"",NOT(OR(LEFT(TRIM($I2),1)="A",LEFT(TRIM($I2),1)="B",LEFT(TRIM($I2),1)="C",LEFT(TRIM($I2),1)="D",LEFT(TRIM($I2),1)="E"))),IF(COUNTIF($Q2:$AG2,"?*")>0,", ","")&"respuesta A-E","") | AI2: =IF(AND(OR($A2="Ítems agrupados por caso clínico o problema",$A2="Opción de Emparejamiento Ampliado"),COUNTIF($D2:$H2,"?*")>0),IF(COUNTIF($Q2:$AH2,"?*")>0,", ","")&"sin incisos","") | AJ2: =IF(AND($A2="Emparejamiento Ampliado",COUNTIF($D2:$H2,"?*")<2),IF(COUNTIF($Q2:$AI2,"?*")>0,", ","")&"minimo 2 claves","") | AK2: =IF(AND($A2="Opción de Emparejamiento Ampliado",NOT(OR(LEFT(TRIM($I2),1)="A",LEFT(TRIM($I2),1)="B",LEFT(TRIM($I2),1)="C",LEFT(TRIM($I2),1)="D",LEFT(TRIM($I2),1)="E"))),IF(COUNTIF($Q2:$AJ2,"?*")>0,", ","")&"respuesta A-E","") | AL2: =IF(TRIM($K2)="",IF(COUNTIF($M2:$M2,"?*")>0,", ","")&"parcial","") | AM2: =IF(AND(TRIM($K2)<>"",TRIM($K2)<>VALIDACIONES!$G$1),IF(COUNTIF($M2:$N2,"?*")>0,", ","")&"parcial distinto a "&VALIDACIONES!$G$1,"") | AN2: =IF(AND(OR($A2="Ítems agrupados por caso clínico o problema",$A2="Subítem de caso o problema",$A2="Emparejamiento Ampliado",$A2="Opción de Emparejamiento Ampliado"),TRIM($B2)=""),IF(COUNTIF($M2:$O2,"?*")>0,", ","")&"grupo","") | AO2: Fáciles (1) | AP2: =COUNTIF($J$2:$J$1001,1) | AQ2: Meta: 15
D3: =IF($A3="Verdadero o Falso Simple","Verdadero",IF($A3="Respuesta A/B/Ambas/Ninguna","A. Si la primera es verdadera",IF($A3="Verdadero o Falso Complejas","1. ",""))) | E3: =IF($A3="Verdadero o Falso Simple","Falso",IF($A3="Respuesta A/B/Ambas/Ninguna","B. Si la segunda es verdadera",IF($A3="Verdadero o Falso Complejas","2. ",""))) | F3: =IF($A3="Respuesta A/B/Ambas/Ninguna","C. Si ambas son verdaderas",IF($A3="Verdadero o Falso Complejas","3. ","")) | G3: =IF($A3="Respuesta A/B/Ambas/Ninguna","D. Si ninguna es verdadera",IF($A3="Verdadero o Falso Complejas","4. ","")) | H3: =IF($A3="Verdadero o Falso Simple","",IF($A3="Respuesta A/B/Ambas/Ninguna","",IF($A3="Verdadero o Falso Complejas","",""))) | J3: 1 | K3: 2P | L3: =IF(TRIM($A3)="","",IF(OR($A3="Selección de la mejor respuesta",$A3="SELECCION_MEJOR_RESPUESTA",$A3="Subítem de caso o problema",$A3="SUBITEM_CASO"),IF(TRIM($C3)="","Completar enunciado",IF(SUMPRODUCT(--(LEN(TRIM($D3:$H3&""))>0))<5,"Completar opciones A-E",IF(AND(TRIM($I3)<>"",OR(LEFT(TRIM($I3),1)="A",LEFT(TRIM($I3),1)="B",LEFT(TRIM($I3),1)="C",LEFT(TRIM($I3),1)="D",LEFT(TRIM($I3),1)="E")),"OK","Completar respuesta correcta A-E"))),IF(TRIM($A3)="","",IF(COUNTIF($Q3:$AJ3,"?*")=0,"OK","Falta revisar: "&$Q3&$R3&$S3&$T3&$U3&$V3&$W3&$X3&$Y3&$Z3&$AA3&$AB3&$AC3&$AD3&$AE3&$AF3&$AG3&$AH3&$AI3&$AJ3)))) | Q3: =IF(TRIM($C3)="","enunciado","") | R3: =IF(TRIM($K3)="",IF(COUNTIF($Q3:$Q3,"?*")>0,", ","")&"parcial","") | S3: =IF(AND(TRIM($K3)<>"",TRIM($K3)<>VALIDACIONES!$G$1),IF(COUNTIF($Q3:$R3,"?*")>0,", ","")&"parcial distinto a "&VALIDACIONES!$G$1,"") | T3: =IF(AND(OR($A3="Ítems agrupados por caso clínico o problema",$A3="Subítem de caso o problema",$A3="Emparejamiento Ampliado",$A3="Opción de Emparejamiento Ampliado"),TRIM($B3)=""),IF(COUNTIF($Q3:$S3,"?*")>0,", ","")&"grupo","") | U3: =IF(AND(OR($A3="Verdadero o Falso Simple",$A3="Respuesta A/B/Ambas/Ninguna",$A3="Verdadero o Falso Complejas",$A3="Selección de la mejor respuesta",$A3="Subítem de caso o problema",$A3="Opción de Emparejamiento Ampliado"),TRIM($I3)=""),IF(COUNTIF($Q3:$T3,"?*")>0,", ","")&"respuesta_correcta","") | V3: =IF(AND(OR($A3="Verdadero o Falso Simple",$A3="Respuesta A/B/Ambas/Ninguna",$A3="Verdadero o Falso Complejas",$A3="Selección de la mejor respuesta",$A3="Subítem de caso o problema",$A3="Opción de Emparejamiento Ampliado"),TRIM($J3)=""),IF(COUNTIF($Q3:$U3,"?*")>0,", ","")&"dificultad","") | W3: =IF(AND(OR($A3="Ítems agrupados por caso clínico o problema",$A3="Emparejamiento Ampliado"),TRIM($I3)<>""),IF(COUNTIF($Q3:$V3,"?*")>0,", ","")&"respuesta debe ir vacia","") | X3: =IF(AND(OR($A3="Ítems agrupados por caso clínico o problema",$A3="Emparejamiento Ampliado"),TRIM($J3)<>""),IF(COUNTIF($Q3:$W3,"?*")>0,", ","")&"dificultad debe ir vacia","") | Y3: =IF(AND($A3="Verdadero o Falso Simple",OR(COUNTIF($D3:$E3,"?*")<2,COUNTIF($F3:$H3,"?*")>0)),IF(COUNTIF($Q3:$X3,"?*")>0,", ","")&"incisos A-B","") | Z3: =IF(AND($A3="Verdadero o Falso Simple",TRIM($I3)<>"",NOT(OR(LEFT(TRIM($I3),1)="A",LEFT(TRIM($I3),1)="B"))),IF(COUNTIF($Q3:$Y3,"?*")>0,", ","")&"respuesta A-B","") | AA3: =IF(AND($A3="Respuesta A/B/Ambas/Ninguna",COUNTIF($D3:$G3,"?*")<4),IF(COUNTIF($Q3:$Z3,"?*")>0,", ","")&"opciones A-D","") | AB3: =IF(AND($A3="Respuesta A/B/Ambas/Ninguna",COUNTIF($H3:$H3,"?*")>0),IF(COUNTIF($Q3:$AA3,"?*")>0,", ","")&"opcion E deshabilitada","") | AC3: =IF(AND($A3="Respuesta A/B/Ambas/Ninguna",TRIM($I3)<>"",NOT(OR(LEFT(TRIM($I3),1)="A",LEFT(TRIM($I3),1)="B",LEFT(TRIM($I3),1)="C",LEFT(TRIM($I3),1)="D"))),IF(COUNTIF($Q3:$AB3,"?*")>0,", ","")&"respuesta A-D","") | AD3: =IF(AND($A3="Verdadero o Falso Complejas",OR(LEN(TRIM(SUBSTITUTE($D3,"1.","")))=0,LEN(TRIM(SUBSTITUTE($E3,"2.","")))=0,LEN(TRIM(SUBSTITUTE($F3,"3.","")))=0,LEN(TRIM(SUBSTITUTE($G3,"4.","")))=0)),IF(COUNTIF($Q3:$AC3,"?*")>0,", ","")&"incisos 1-4","") | AE3: =IF(AND($A3="Verdadero o Falso Complejas",COUNTIF($H3:$H3,"?*")>0),IF(COUNTIF($Q3:$AD3,"?*")>0,", ","")&"opcion E deshabilitada","") | AF3: =IF(AND($A3="Verdadero o Falso Complejas",TRIM($I3)<>"",NOT(OR(LEFT(TRIM($I3),1)="A",LEFT(TRIM($I3),1)="B",LEFT(TRIM($I3),1)="C",LEFT(TRIM($I3),1)="D",LEFT(TRIM($I3),1)="E"))),IF(COUNTIF($Q3:$AE3,"?*")>0,", ","")&"respuesta A-E","") | AG3: =IF(AND(OR($A3="Selección de la mejor respuesta",$A3="Subítem de caso o problema"),COUNTA($D3:$H3)<5),IF(COUNTIF($Q3:$AF3,"?*")>0,", ","")&"incisos A-E","") | AH3: =IF(AND(OR($A3="Selección de la mejor respuesta",$A3="Subítem de caso o problema"),TRIM($I3)<>"",NOT(OR(LEFT(TRIM($I3),1)="A",LEFT(TRIM($I3),1)="B",LEFT(TRIM($I3),1)="C",LEFT(TRIM($I3),1)="D",LEFT(TRIM($I3),1)="E"))),IF(COUNTIF($Q3:$AG3,"?*")>0,", ","")&"respuesta A-E","") | AI3: =IF(AND(OR($A3="Ítems agrupados por caso clínico o problema",$A3="Opción de Emparejamiento Ampliado"),COUNTIF($D3:$H3,"?*")>0),IF(COUNTIF($Q3:$AH3,"?*")>0,", ","")&"sin incisos","") | AJ3: =IF(AND($A3="Emparejamiento Ampliado",COUNTIF($D3:$H3,"?*")<2),IF(COUNTIF($Q3:$AI3,"?*")>0,", ","")&"minimo 2 claves","") | AK3: =IF(AND($A3="Opción de Emparejamiento Ampliado",NOT(OR(LEFT(TRIM($I3),1)="A",LEFT(TRIM($I3),1)="B",LEFT(TRIM($I3),1)="C",LEFT(TRIM($I3),1)="D",LEFT(TRIM($I3),1)="E"))),IF(COUNTIF($Q3:$AJ3,"?*")>0,", ","")&"respuesta A-E","") | AL3: =IF(TRIM($K3)="",IF(COUNTIF($M3:$M3,"?*")>0,", ","")&"parcial","") | AM3: =IF(AND(TRIM($K3)<>"",TRIM($K3)<>VALIDACIONES!$G$1),IF(COUNTIF($M3:$N3,"?*")>0,", ","")&"parcial distinto a "&VALIDACIONES!$G$1,"") | AN3: =IF(AND(OR($A3="Ítems agrupados por caso clínico o problema",$A3="Subítem de caso o problema",$A3="Emparejamiento Ampliado",$A3="Opción de Emparejamiento Ampliado"),TRIM($B3)=""),IF(COUNTIF($M3:$O3,"?*")>0,", ","")&"grupo","") | AO3: Medias (2) | AP3: =COUNTIF($J$2:$J$1001,2) | AQ3: Meta: 30
D4: =IF($A4="Verdadero o Falso Simple","Verdadero",IF($A4="Respuesta A/B/Ambas/Ninguna","A. Si la primera es verdadera",IF($A4="Verdadero o Falso Complejas","1. ",""))) | E4: =IF($A4="Verdadero o Falso Simple","Falso",IF($A4="Respuesta A/B/Ambas/Ninguna","B. Si la segunda es verdadera",IF($A4="Verdadero o Falso Complejas","2. ",""))) | F4: =IF($A4="Respuesta A/B/Ambas/Ninguna","C. Si ambas son verdaderas",IF($A4="Verdadero o Falso Complejas","3. ","")) | G4: =IF($A4="Respuesta A/B/Ambas/Ninguna","D. Si ninguna es verdadera",IF($A4="Verdadero o Falso Complejas","4. ","")) | H4: =IF($A4="Verdadero o Falso Simple","",IF($A4="Respuesta A/B/Ambas/Ninguna","",IF($A4="Verdadero o Falso Complejas","",""))) | J4: 1 | K4: 2P | L4: =IF(TRIM($A4)="","",IF(OR($A4="Selección de la mejor respuesta",$A4="SELECCION_MEJOR_RESPUESTA",$A4="Subítem de caso o problema",$A4="SUBITEM_CASO"),IF(TRIM($C4)="","Completar enunciado",IF(SUMPRODUCT(--(LEN(TRIM($D4:$H4&""))>0))<5,"Completar opciones A-E",IF(AND(TRIM($I4)<>"",OR(LEFT(TRIM($I4),1)="A",LEFT(TRIM($I4),1)="B",LEFT(TRIM($I4),1)="C",LEFT(TRIM($I4),1)="D",LEFT(TRIM($I4),1)="E")),"OK","Completar respuesta correcta A-E"))),IF(TRIM($A4)="","",IF(COUNTIF($Q4:$AJ4,"?*")=0,"OK","Falta revisar: "&$Q4&$R4&$S4&$T4&$U4&$V4&$W4&$X4&$Y4&$Z4&$AA4&$AB4&$AC4&$AD4&$AE4&$AF4&$AG4&$AH4&$AI4&$AJ4)))) | Q4: =IF(TRIM($C4)="","enunciado","") | R4: =IF(TRIM($K4)="",IF(COUNTIF($Q4:$Q4,"?*")>0,", ","")&"parcial","") | S4: =IF(AND(TRIM($K4)<>"",TRIM($K4)<>VALIDACIONES!$G$1),IF(COUNTIF($Q4:$R4,"?*")>0,", ","")&"parcial distinto a "&VALIDACIONES!$G$1,"") | T4: =IF(AND(OR($A4="Ítems agrupados por caso clínico o problema",$A4="Subítem de caso o problema",$A4="Emparejamiento Ampliado",$A4="Opción de Emparejamiento Ampliado"),TRIM($B4)=""),IF(COUNTIF($Q4:$S4,"?*")>0,", ","")&"grupo","") | U4: =IF(AND(OR($A4="Verdadero o Falso Simple",$A4="Respuesta A/B/Ambas/Ninguna",$A4="Verdadero o Falso Complejas",$A4="Selección de la mejor respuesta",$A4="Subítem de caso o problema",$A4="Opción de Emparejamiento Ampliado"),TRIM($I4)=""),IF(COUNTIF($Q4:$T4,"?*")>0,", ","")&"respuesta_correcta","") | V4: =IF(AND(OR($A4="Verdadero o Falso Simple",$A4="Respuesta A/B/Ambas/Ninguna",$A4="Verdadero o Falso Complejas",$A4="Selección de la mejor respuesta",$A4="Subítem de caso o problema",$A4="Opción de Emparejamiento Ampliado"),TRIM($J4)=""),IF(COUNTIF($Q4:$U4,"?*")>0,", ","")&"dificultad","") | W4: =IF(AND(OR($A4="Ítems agrupados por caso clínico o problema",$A4="Emparejamiento Ampliado"),TRIM($I4)<>""),IF(COUNTIF($Q4:$V4,"?*")>0,", ","")&"respuesta debe ir vacia","") | X4: =IF(AND(OR($A4="Ítems agrupados por caso clínico o problema",$A4="Emparejamiento Ampliado"),TRIM($J4)<>""),IF(COUNTIF($Q4:$W4,"?*")>0,", ","")&"dificultad debe ir vacia","") | Y4: =IF(AND($A4="Verdadero o Falso Simple",OR(COUNTIF($D4:$E4,"?*")<2,COUNTIF($F4:$H4,"?*")>0)),IF(COUNTIF($Q4:$X4,"?*")>0,", ","")&"incisos A-B","") | Z4: =IF(AND($A4="Verdadero o Falso Simple",TRIM($I4)<>"",NOT(OR(LEFT(TRIM($I4),1)="A",LEFT(TRIM($I4),1)="B"))),IF(COUNTIF($Q4:$Y4,"?*")>0,", ","")&"respuesta A-B","") | AA4: =IF(AND($A4="Respuesta A/B/Ambas/Ninguna",COUNTIF($D4:$G4,"?*")<4),IF(COUNTIF($Q4:$Z4,"?*")>0,", ","")&"opciones A-D","") | AB4: =IF(AND($A4="Respuesta A/B/Ambas/Ninguna",COUNTIF($H4:$H4,"?*")>0),IF(COUNTIF($Q4:$AA4,"?*")>0,", ","")&"opcion E deshabilitada","") | AC4: =IF(AND($A4="Respuesta A/B/Ambas/Ninguna",TRIM($I4)<>"",NOT(OR(LEFT(TRIM($I4),1)="A",LEFT(TRIM($I4),1)="B",LEFT(TRIM($I4),1)="C",LEFT(TRIM($I4),1)="D"))),IF(COUNTIF($Q4:$AB4,"?*")>0,", ","")&"respuesta A-D","") | AD4: =IF(AND($A4="Verdadero o Falso Complejas",OR(LEN(TRIM(SUBSTITUTE($D4,"1.","")))=0,LEN(TRIM(SUBSTITUTE($E4,"2.","")))=0,LEN(TRIM(SUBSTITUTE($F4,"3.","")))=0,LEN(TRIM(SUBSTITUTE($G4,"4.","")))=0)),IF(COUNTIF($Q4:$AC4,"?*")>0,", ","")&"incisos 1-4","") | AE4: =IF(AND($A4="Verdadero o Falso Complejas",COUNTIF($H4:$H4,"?*")>0),IF(COUNTIF($Q4:$AD4,"?*")>0,", ","")&"opcion E deshabilitada","") | AF4: =IF(AND($A4="Verdadero o Falso Complejas",TRIM($I4)<>"",NOT(OR(LEFT(TRIM($I4),1)="A",LEFT(TRIM($I4),1)="B",LEFT(TRIM($I4),1)="C",LEFT(TRIM($I4),1)="D",LEFT(TRIM($I4),1)="E"))),IF(COUNTIF($Q4:$AE4,"?*")>0,", ","")&"respuesta A-E","") | AG4: =IF(AND(OR($A4="Selección de la mejor respuesta",$A4="Subítem de caso o problema"),COUNTA($D4:$H4)<5),IF(COUNTIF($Q4:$AF4,"?*")>0,", ","")&"incisos A-E","") | AH4: =IF(AND(OR($A4="Selección de la mejor respuesta",$A4="Subítem de caso o problema"),TRIM($I4)<>"",NOT(OR(LEFT(TRIM($I4),1)="A",LEFT(TRIM($I4),1)="B",LEFT(TRIM($I4),1)="C",LEFT(TRIM($I4),1)="D",LEFT(TRIM($I4),1)="E"))),IF(COUNTIF($Q4:$AG4,"?*")>0,", ","")&"respuesta A-E","") | AI4: =IF(AND(OR($A4="Ítems agrupados por caso clínico o problema",$A4="Opción de Emparejamiento Ampliado"),COUNTIF($D4:$H4,"?*")>0),IF(COUNTIF($Q4:$AH4,"?*")>0,", ","")&"sin incisos","") | AJ4: =IF(AND($A4="Emparejamiento Ampliado",COUNTIF($D4:$H4,"?*")<2),IF(COUNTIF($Q4:$AI4,"?*")>0,", ","")&"minimo 2 claves","") | AK4: =IF(AND($A4="Opción de Emparejamiento Ampliado",NOT(OR(LEFT(TRIM($I4),1)="A",LEFT(TRIM($I4),1)="B",LEFT(TRIM($I4),1)="C",LEFT(TRIM($I4),1)="D",LEFT(TRIM($I4),1)="E"))),IF(COUNTIF($Q4:$AJ4,"?*")>0,", ","")&"respuesta A-E","") | AL4: =IF(TRIM($K4)="",IF(COUNTIF($M4:$M4,"?*")>0,", ","")&"parcial","") | AM4: =IF(AND(TRIM($K4)<>"",TRIM($K4)<>VALIDACIONES!$G$1),IF(COUNTIF($M4:$N4,"?*")>0,", ","")&"parcial distinto a "&VALIDACIONES!$G$1,"") | AN4: =IF(AND(OR($A4="Ítems agrupados por caso clínico o problema",$A4="Subítem de caso o problema",$A4="Emparejamiento Ampliado",$A4="Opción de Emparejamiento Ampliado"),TRIM($B4)=""),IF(COUNTIF($M4:$O4,"?*")>0,", ","")&"grupo","") | AO4: Difíciles (3) | AP4: =COUNTIF($J$2:$J$1001,3) | AQ4: Meta: 15
D5: =IF($A5="Verdadero o Falso Simple","Verdadero",IF($A5="Respuesta A/B/Ambas/Ninguna","A. Si la primera es verdadera",IF($A5="Verdadero o Falso Complejas","1. ",""))) | E5: =IF($A5="Verdadero o Falso Simple","Falso",IF($A5="Respuesta A/B/Ambas/Ninguna","B. Si la segunda es verdadera",IF($A5="Verdadero o Falso Complejas","2. ",""))) | F5: =IF($A5="Respuesta A/B/Ambas/Ninguna","C. Si ambas son verdaderas",IF($A5="Verdadero o Falso Complejas","3. ","")) | G5: =IF($A5="Respuesta A/B/Ambas/Ninguna","D. Si ninguna es verdadera",IF($A5="Verdadero o Falso Complejas","4. ","")) | H5: =IF($A5="Verdadero o Falso Simple","",IF($A5="Respuesta A/B/Ambas/Ninguna","",IF($A5="Verdadero o Falso Complejas","",""))) | J5: 1 | K5: 2P | L5: =IF(TRIM($A5)="","",IF(OR($A5="Selección de la mejor respuesta",$A5="SELECCION_MEJOR_RESPUESTA",$A5="Subítem de caso o problema",$A5="SUBITEM_CASO"),IF(TRIM($C5)="","Completar enunciado",IF(SUMPRODUCT(--(LEN(TRIM($D5:$H5&""))>0))<5,"Completar opciones A-E",IF(AND(TRIM($I5)<>"",OR(LEFT(TRIM($I5),1)="A",LEFT(TRIM($I5),1)="B",LEFT(TRIM($I5),1)="C",LEFT(TRIM($I5),1)="D",LEFT(TRIM($I5),1)="E")),"OK","Completar respuesta correcta A-E"))),IF(TRIM($A5)="","",IF(COUNTIF($Q5:$AJ5,"?*")=0,"OK","Falta revisar: "&$Q5&$R5&$S5&$T5&$U5&$V5&$W5&$X5&$Y5&$Z5&$AA5&$AB5&$AC5&$AD5&$AE5&$AF5&$AG5&$AH5&$AI5&$AJ5)))) | Q5: =IF(TRIM($C5)="","enunciado","") | R5: =IF(TRIM($K5)="",IF(COUNTIF($Q5:$Q5,"?*")>0,", ","")&"parcial","") | S5: =IF(AND(TRIM($K5)<>"",TRIM($K5)<>VALIDACIONES!$G$1),IF(COUNTIF($Q5:$R5,"?*")>0,", ","")&"parcial distinto a "&VALIDACIONES!$G$1,"") | T5: =IF(AND(OR($A5="Ítems agrupados por caso clínico o problema",$A5="Subítem de caso o problema",$A5="Emparejamiento Ampliado",$A5="Opción de Emparejamiento Ampliado"),TRIM($B5)=""),IF(COUNTIF($Q5:$S5,"?*")>0,", ","")&"grupo","") | U5: =IF(AND(OR($A5="Verdadero o Falso Simple",$A5="Respuesta A/B/Ambas/Ninguna",$A5="Verdadero o Falso Complejas",$A5="Selección de la mejor respuesta",$A5="Subítem de caso o problema",$A5="Opción de Emparejamiento Ampliado"),TRIM($I5)=""),IF(COUNTIF($Q5:$T5,"?*")>0,", ","")&"respuesta_correcta","") | V5: =IF(AND(OR($A5="Verdadero o Falso Simple",$A5="Respuesta A/B/Ambas/Ninguna",$A5="Verdadero o Falso Complejas",$A5="Selección de la mejor respuesta",$A5="Subítem de caso o problema",$A5="Opción de Emparejamiento Ampliado"),TRIM($J5)=""),IF(COUNTIF($Q5:$U5,"?*")>0,", ","")&"dificultad","") | W5: =IF(AND(OR($A5="Ítems agrupados por caso clínico o problema",$A5="Emparejamiento Ampliado"),TRIM($I5)<>""),IF(COUNTIF($Q5:$V5,"?*")>0,", ","")&"respuesta debe ir vacia","") | X5: =IF(AND(OR($A5="Ítems agrupados por caso clínico o problema",$A5="Emparejamiento Ampliado"),TRIM($J5)<>""),IF(COUNTIF($Q5:$W5,"?*")>0,", ","")&"dificultad debe ir vacia","") | Y5: =IF(AND($A5="Verdadero o Falso Simple",OR(COUNTIF($D5:$E5,"?*")<2,COUNTIF($F5:$H5,"?*")>0)),IF(COUNTIF($Q5:$X5,"?*")>0,", ","")&"incisos A-B","") | Z5: =IF(AND($A5="Verdadero o Falso Simple",TRIM($I5)<>"",NOT(OR(LEFT(TRIM($I5),1)="A",LEFT(TRIM($I5),1)="B"))),IF(COUNTIF($Q5:$Y5,"?*")>0,", ","")&"respuesta A-B","") | AA5: =IF(AND($A5="Respuesta A/B/Ambas/Ninguna",COUNTIF($D5:$G5,"?*")<4),IF(COUNTIF($Q5:$Z5,"?*")>0,", ","")&"opciones A-D","") | AB5: =IF(AND($A5="Respuesta A/B/Ambas/Ninguna",COUNTIF($H5:$H5,"?*")>0),IF(COUNTIF($Q5:$AA5,"?*")>0,", ","")&"opcion E deshabilitada","") | AC5: =IF(AND($A5="Respuesta A/B/Ambas/Ninguna",TRIM($I5)<>"",NOT(OR(LEFT(TRIM($I5),1)="A",LEFT(TRIM($I5),1)="B",LEFT(TRIM($I5),1)="C",LEFT(TRIM($I5),1)="D"))),IF(COUNTIF($Q5:$AB5,"?*")>0,", ","")&"respuesta A-D","") | AD5: =IF(AND($A5="Verdadero o Falso Complejas",OR(LEN(TRIM(SUBSTITUTE($D5,"1.","")))=0,LEN(TRIM(SUBSTITUTE($E5,"2.","")))=0,LEN(TRIM(SUBSTITUTE($F5,"3.","")))=0,LEN(TRIM(SUBSTITUTE($G5,"4.","")))=0)),IF(COUNTIF($Q5:$AC5,"?*")>0,", ","")&"incisos 1-4","") | AE5: =IF(AND($A5="Verdadero o Falso Complejas",COUNTIF($H5:$H5,"?*")>0),IF(COUNTIF($Q5:$AD5,"?*")>0,", ","")&"opcion E deshabilitada","") | AF5: =IF(AND($A5="Verdadero o Falso Complejas",TRIM($I5)<>"",NOT(OR(LEFT(TRIM($I5),1)="A",LEFT(TRIM($I5),1)="B",LEFT(TRIM($I5),1)="C",LEFT(TRIM($I5),1)="D",LEFT(TRIM($I5),1)="E"))),IF(COUNTIF($Q5:$AE5,"?*")>0,", ","")&"respuesta A-E","") | AG5: =IF(AND(OR($A5="Selección de la mejor respuesta",$A5="Subítem de caso o problema"),COUNTA($D5:$H5)<5),IF(COUNTIF($Q5:$AF5,"?*")>0,", ","")&"incisos A-E","") | AH5: =IF(AND(OR($A5="Selección de la mejor respuesta",$A5="Subítem de caso o problema"),TRIM($I5)<>"",NOT(OR(LEFT(TRIM($I5),1)="A",LEFT(TRIM($I5),1)="B",LEFT(TRIM($I5),1)="C",LEFT(TRIM($I5),1)="D",LEFT(TRIM($I5),1)="E"))),IF(COUNTIF($Q5:$AG5,"?*")>0,", ","")&"respuesta A-E","") | AI5: =IF(AND(OR($A5="Ítems agrupados por caso clínico o problema",$A5="Opción de Emparejamiento Ampliado"),COUNTIF($D5:$H5,"?*")>0),IF(COUNTIF($Q5:$AH5,"?*")>0,", ","")&"sin incisos","") | AJ5: =IF(AND($A5="Emparejamiento Ampliado",COUNTIF($D5:$H5,"?*")<2),IF(COUNTIF($Q5:$AI5,"?*")>0,", ","")&"minimo 2 claves","") | AK5: =IF(AND($A5="Opción de Emparejamiento Ampliado",NOT(OR(LEFT(TRIM($I5),1)="A",LEFT(TRIM($I5),1)="B",LEFT(TRIM($I5),1)="C",LEFT(TRIM($I5),1)="D",LEFT(TRIM($I5),1)="E"))),IF(COUNTIF($Q5:$AJ5,"?*")>0,", ","")&"respuesta A-E","") | AL5: =IF(TRIM($K5)="",IF(COUNTIF($M5:$M5,"?*")>0,", ","")&"parcial","") | AM5: =IF(AND(TRIM($K5)<>"",TRIM($K5)<>VALIDACIONES!$G$1),IF(COUNTIF($M5:$N5,"?*")>0,", ","")&"parcial distinto a "&VALIDACIONES!$G$1,"") | AN5: =IF(AND(OR($A5="Ítems agrupados por caso clínico o problema",$A5="Subítem de caso o problema",$A5="Emparejamiento Ampliado",$A5="Opción de Emparejamiento Ampliado"),TRIM($B5)=""),IF(COUNTIF($M5:$O5,"?*")>0,", ","")&"grupo","") | AO5: Total Dificultad | AP5: =SUM(AP2:AP4) | AQ5: Meta: 60
D6: =IF($A6="Verdadero o Falso Simple","Verdadero",IF($A6="Respuesta A/B/Ambas/Ninguna","A. Si la primera es verdadera",IF($A6="Verdadero o Falso Complejas","1. ",""))) | E6: =IF($A6="Verdadero o Falso Simple","Falso",IF($A6="Respuesta A/B/Ambas/Ninguna","B. Si la segunda es verdadera",IF($A6="Verdadero o Falso Complejas","2. ",""))) | F6: =IF($A6="Respuesta A/B/Ambas/Ninguna","C. Si ambas son verdaderas",IF($A6="Verdadero o Falso Complejas","3. ","")) | G6: =IF($A6="Respuesta A/B/Ambas/Ninguna","D. Si ninguna es verdadera",IF($A6="Verdadero o Falso Complejas","4. ","")) | H6: =IF($A6="Verdadero o Falso Simple","",IF($A6="Respuesta A/B/Ambas/Ninguna","",IF($A6="Verdadero o Falso Complejas","",""))) | J6: 1 | K6: 2P | L6: =IF(TRIM($A6)="","",IF(OR($A6="Selección de la mejor respuesta",$A6="SELECCION_MEJOR_RESPUESTA",$A6="Subítem de caso o problema",$A6="SUBITEM_CASO"),IF(TRIM($C6)="","Completar enunciado",IF(SUMPRODUCT(--(LEN(TRIM($D6:$H6&""))>0))<5,"Completar opciones A-E",IF(AND(TRIM($I6)<>"",OR(LEFT(TRIM($I6),1)="A",LEFT(TRIM($I6),1)="B",LEFT(TRIM($I6),1)="C",LEFT(TRIM($I6),1)="D",LEFT(TRIM($I6),1)="E")),"OK","Completar respuesta correcta A-E"))),IF(TRIM($A6)="","",IF(COUNTIF($Q6:$AJ6,"?*")=0,"OK","Falta revisar: "&$Q6&$R6&$S6&$T6&$U6&$V6&$W6&$X6&$Y6&$Z6&$AA6&$AB6&$AC6&$AD6&$AE6&$AF6&$AG6&$AH6&$AI6&$AJ6)))) | Q6: =IF(TRIM($C6)="","enunciado","") | R6: =IF(TRIM($K6)="",IF(COUNTIF($Q6:$Q6,"?*")>0,", ","")&"parcial","") | S6: =IF(AND(TRIM($K6)<>"",TRIM($K6)<>VALIDACIONES!$G$1),IF(COUNTIF($Q6:$R6,"?*")>0,", ","")&"parcial distinto a "&VALIDACIONES!$G$1,"") | T6: =IF(AND(OR($A6="Ítems agrupados por caso clínico o problema",$A6="Subítem de caso o problema",$A6="Emparejamiento Ampliado",$A6="Opción de Emparejamiento Ampliado"),TRIM($B6)=""),IF(COUNTIF($Q6:$S6,"?*")>0,", ","")&"grupo","") | U6: =IF(AND(OR($A6="Verdadero o Falso Simple",$A6="Respuesta A/B/Ambas/Ninguna",$A6="Verdadero o Falso Complejas",$A6="Selección de la mejor respuesta",$A6="Subítem de caso o problema",$A6="Opción de Emparejamiento Ampliado"),TRIM($I6)=""),IF(COUNTIF($Q6:$T6,"?*")>0,", ","")&"respuesta_correcta","") | V6: =IF(AND(OR($A6="Verdadero o Falso Simple",$A6="Respuesta A/B/Ambas/Ninguna",$A6="Verdadero o Falso Complejas",$A6="Selección de la mejor respuesta",$A6="Subítem de caso o problema",$A6="Opción de Emparejamiento Ampliado"),TRIM($J6)=""),IF(COUNTIF($Q6:$U6,"?*")>0,", ","")&"dificultad","") | W6: =IF(AND(OR($A6="Ítems agrupados por caso clínico o problema",$A6="Emparejamiento Ampliado"),TRIM($I6)<>""),IF(COUNTIF($Q6:$V6,"?*")>0,", ","")&"respuesta debe ir vacia","") | X6: =IF(AND(OR($A6="Ítems agrupados por caso clínico o problema",$A6="Emparejamiento Ampliado"),TRIM($J6)<>""),IF(COUNTIF($Q6:$W6,"?*")>0,", ","")&"dificultad debe ir vacia","") | Y6: =IF(AND($A6="Verdadero o Falso Simple",OR(COUNTIF($D6:$E6,"?*")<2,COUNTIF($F6:$H6,"?*")>0)),IF(COUNTIF($Q6:$X6,"?*")>0,", ","")&"incisos A-B","") | Z6: =IF(AND($A6="Verdadero o Falso Simple",TRIM($I6)<>"",NOT(OR(LEFT(TRIM($I6),1)="A",LEFT(TRIM($I6),1)="B"))),IF(COUNTIF($Q6:$Y6,"?*")>0,", ","")&"respuesta A-B","") | AA6: =IF(AND($A6="Respuesta A/B/Ambas/Ninguna",COUNTIF($D6:$G6,"?*")<4),IF(COUNTIF($Q6:$Z6,"?*")>0,", ","")&"opciones A-D","") | AB6: =IF(AND($A6="Respuesta A/B/Ambas/Ninguna",COUNTIF($H6:$H6,"?*")>0),IF(COUNTIF($Q6:$AA6,"?*")>0,", ","")&"opcion E deshabilitada","") | AC6: =IF(AND($A6="Respuesta A/B/Ambas/Ninguna",TRIM($I6)<>"",NOT(OR(LEFT(TRIM($I6),1)="A",LEFT(TRIM($I6),1)="B",LEFT(TRIM($I6),1)="C",LEFT(TRIM($I6),1)="D"))),IF(COUNTIF($Q6:$AB6,"?*")>0,", ","")&"respuesta A-D","") | AD6: =IF(AND($A6="Verdadero o Falso Complejas",OR(LEN(TRIM(SUBSTITUTE($D6,"1.","")))=0,LEN(TRIM(SUBSTITUTE($E6,"2.","")))=0,LEN(TRIM(SUBSTITUTE($F6,"3.","")))=0,LEN(TRIM(SUBSTITUTE($G6,"4.","")))=0)),IF(COUNTIF($Q6:$AC6,"?*")>0,", ","")&"incisos 1-4","") | AE6: =IF(AND($A6="Verdadero o Falso Complejas",COUNTIF($H6:$H6,"?*")>0),IF(COUNTIF($Q6:$AD6,"?*")>0,", ","")&"opcion E deshabilitada","") | AF6: =IF(AND($A6="Verdadero o Falso Complejas",TRIM($I6)<>"",NOT(OR(LEFT(TRIM($I6),1)="A",LEFT(TRIM($I6),1)="B",LEFT(TRIM($I6),1)="C",LEFT(TRIM($I6),1)="D",LEFT(TRIM($I6),1)="E"))),IF(COUNTIF($Q6:$AE6,"?*")>0,", ","")&"respuesta A-E","") | AG6: =IF(AND(OR($A6="Selección de la mejor respuesta",$A6="Subítem de caso o problema"),COUNTA($D6:$H6)<5),IF(COUNTIF($Q6:$AF6,"?*")>0,", ","")&"incisos A-E","") | AH6: =IF(AND(OR($A6="Selección de la mejor respuesta",$A6="Subítem de caso o problema"),TRIM($I6)<>"",NOT(OR(LEFT(TRIM($I6),1)="A",LEFT(TRIM($I6),1)="B",LEFT(TRIM($I6),1)="C",LEFT(TRIM($I6),1)="D",LEFT(TRIM($I6),1)="E"))),IF(COUNTIF($Q6:$AG6,"?*")>0,", ","")&"respuesta A-E","") | AI6: =IF(AND(OR($A6="Ítems agrupados por caso clínico o problema",$A6="Opción de Emparejamiento Ampliado"),COUNTIF($D6:$H6,"?*")>0),IF(COUNTIF($Q6:$AH6,"?*")>0,", ","")&"sin incisos","") | AJ6: =IF(AND($A6="Emparejamiento Ampliado",COUNTIF($D6:$H6,"?*")<2),IF(COUNTIF($Q6:$AI6,"?*")>0,", ","")&"minimo 2 claves","") | AK6: =IF(AND($A6="Opción de Emparejamiento Ampliado",NOT(OR(LEFT(TRIM($I6),1)="A",LEFT(TRIM($I6),1)="B",LEFT(TRIM($I6),1)="C",LEFT(TRIM($I6),1)="D",LEFT(TRIM($I6),1)="E"))),IF(COUNTIF($Q6:$AJ6,"?*")>0,", ","")&"respuesta A-E","") | AL6: =IF(TRIM($K6)="",IF(COUNTIF($M6:$M6,"?*")>0,", ","")&"parcial","") | AM6: =IF(AND(TRIM($K6)<>"",TRIM($K6)<>VALIDACIONES!$G$1),IF(COUNTIF($M6:$N6,"?*")>0,", ","")&"parcial distinto a "&VALIDACIONES!$G$1,"") | AN6: =IF(AND(OR($A6="Ítems agrupados por caso clínico o problema",$A6="Subítem de caso o problema",$A6="Emparejamiento Ampliado",$A6="Opción de Emparejamiento Ampliado"),TRIM($B6)=""),IF(COUNTIF($M6:$O6,"?*")>0,", ","")&"grupo","") | AO6: Estado Dificultad | AP6: =IF(AND(AP2>=15,AP3>=30,AP4>=15,AP5>=60),"COMPLETA","REVISAR")
D7: =IF($A7="Verdadero o Falso Simple","Verdadero",IF($A7="Respuesta A/B/Ambas/Ninguna","A. Si la primera es verdadera",IF($A7="Verdadero o Falso Complejas","1. ",""))) | E7: =IF($A7="Verdadero o Falso Simple","Falso",IF($A7="Respuesta A/B/Ambas/Ninguna","B. Si la segunda es verdadera",IF($A7="Verdadero o Falso Complejas","2. ",""))) | F7: =IF($A7="Respuesta A/B/Ambas/Ninguna","C. Si ambas son verdaderas",IF($A7="Verdadero o Falso Complejas","3. ","")) | G7: =IF($A7="Respuesta A/B/Ambas/Ninguna","D. Si ninguna es verdadera",IF($A7="Verdadero o Falso Complejas","4. ","")) | H7: =IF($A7="Verdadero o Falso Simple","",IF($A7="Respuesta A/B/Ambas/Ninguna","",IF($A7="Verdadero o Falso Complejas","",""))) | J7: 1 | K7: 2P | L7: =IF(TRIM($A7)="","",IF(OR($A7="Selección de la mejor respuesta",$A7="SELECCION_MEJOR_RESPUESTA",$A7="Subítem de caso o problema",$A7="SUBITEM_CASO"),IF(TRIM($C7)="","Completar enunciado",IF(SUMPRODUCT(--(LEN(TRIM($D7:$H7&""))>0))<5,"Completar opciones A-E",IF(AND(TRIM($I7)<>"",OR(LEFT(TRIM($I7),1)="A",LEFT(TRIM($I7),1)="B",LEFT(TRIM($I7),1)="C",LEFT(TRIM($I7),1)="D",LEFT(TRIM($I7),1)="E")),"OK","Completar respuesta correcta A-E"))),IF(TRIM($A7)="","",IF(COUNTIF($Q7:$AJ7,"?*")=0,"OK","Falta revisar: "&$Q7&$R7&$S7&$T7&$U7&$V7&$W7&$X7&$Y7&$Z7&$AA7&$AB7&$AC7&$AD7&$AE7&$AF7&$AG7&$AH7&$AI7&$AJ7)))) | Q7: =IF(TRIM($C7)="","enunciado","") | R7: =IF(TRIM($K7)="",IF(COUNTIF($Q7:$Q7,"?*")>0,", ","")&"parcial","") | S7: =IF(AND(TRIM($K7)<>"",TRIM($K7)<>VALIDACIONES!$G$1),IF(COUNTIF($Q7:$R7,"?*")>0,", ","")&"parcial distinto a "&VALIDACIONES!$G$1,"") | T7: =IF(AND(OR($A7="Ítems agrupados por caso clínico o problema",$A7="Subítem de caso o problema",$A7="Emparejamiento Ampliado",$A7="Opción de Emparejamiento Ampliado"),TRIM($B7)=""),IF(COUNTIF($Q7:$S7,"?*")>0,", ","")&"grupo","") | U7: =IF(AND(OR($A7="Verdadero o Falso Simple",$A7="Respuesta A/B/Ambas/Ninguna",$A7="Verdadero o Falso Complejas",$A7="Selección de la mejor respuesta",$A7="Subítem de caso o problema",$A7="Opción de Emparejamiento Ampliado"),TRIM($I7)=""),IF(COUNTIF($Q7:$T7,"?*")>0,", ","")&"respuesta_correcta","") | V7: =IF(AND(OR($A7="Verdadero o Falso Simple",$A7="Respuesta A/B/Ambas/Ninguna",$A7="Verdadero o Falso Complejas",$A7="Selección de la mejor respuesta",$A7="Subítem de caso o problema",$A7="Opción de Emparejamiento Ampliado"),TRIM($J7)=""),IF(COUNTIF($Q7:$U7,"?*")>0,", ","")&"dificultad","") | W7: =IF(AND(OR($A7="Ítems agrupados por caso clínico o problema",$A7="Emparejamiento Ampliado"),TRIM($I7)<>""),IF(COUNTIF($Q7:$V7,"?*")>0,", ","")&"respuesta debe ir vacia","") | X7: =IF(AND(OR($A7="Ítems agrupados por caso clínico o problema",$A7="Emparejamiento Ampliado"),TRIM($J7)<>""),IF(COUNTIF($Q7:$W7,"?*")>0,", ","")&"dificultad debe ir vacia","") | Y7: =IF(AND($A7="Verdadero o Falso Simple",OR(COUNTIF($D7:$E7,"?*")<2,COUNTIF($F7:$H7,"?*")>0)),IF(COUNTIF($Q7:$X7,"?*")>0,", ","")&"incisos A-B","") | Z7: =IF(AND($A7="Verdadero o Falso Simple",TRIM($I7)<>"",NOT(OR(LEFT(TRIM($I7),1)="A",LEFT(TRIM($I7),1)="B"))),IF(COUNTIF($Q7:$Y7,"?*")>0,", ","")&"respuesta A-B","") | AA7: =IF(AND($A7="Respuesta A/B/Ambas/Ninguna",COUNTIF($D7:$G7,"?*")<4),IF(COUNTIF($Q7:$Z7,"?*")>0,", ","")&"opciones A-D","") | AB7: =IF(AND($A7="Respuesta A/B/Ambas/Ninguna",COUNTIF($H7:$H7,"?*")>0),IF(COUNTIF($Q7:$AA7,"?*")>0,", ","")&"opcion E deshabilitada","") | AC7: =IF(AND($A7="Respuesta A/B/Ambas/Ninguna",TRIM($I7)<>"",NOT(OR(LEFT(TRIM($I7),1)="A",LEFT(TRIM($I7),1)="B",LEFT(TRIM($I7),1)="C",LEFT(TRIM($I7),1)="D"))),IF(COUNTIF($Q7:$AB7,"?*")>0,", ","")&"respuesta A-D","") | AD7: =IF(AND($A7="Verdadero o Falso Complejas",OR(LEN(TRIM(SUBSTITUTE($D7,"1.","")))=0,LEN(TRIM(SUBSTITUTE($E7,"2.","")))=0,LEN(TRIM(SUBSTITUTE($F7,"3.","")))=0,LEN(TRIM(SUBSTITUTE($G7,"4.","")))=0)),IF(COUNTIF($Q7:$AC7,"?*")>0,", ","")&"incisos 1-4","") | AE7: =IF(AND($A7="Verdadero o Falso Complejas",COUNTIF($H7:$H7,"?*")>0),IF(COUNTIF($Q7:$AD7,"?*")>0,", ","")&"opcion E deshabilitada","") | AF7: =IF(AND($A7="Verdadero o Falso Complejas",TRIM($I7)<>"",NOT(OR(LEFT(TRIM($I7),1)="A",LEFT(TRIM($I7),1)="B",LEFT(TRIM($I7),1)="C",LEFT(TRIM($I7),1)="D",LEFT(TRIM($I7),1)="E"))),IF(COUNTIF($Q7:$AE7,"?*")>0,", ","")&"respuesta A-E","") | AG7: =IF(AND(OR($A7="Selección de la mejor respuesta",$A7="Subítem de caso o problema"),COUNTA($D7:$H7)<5),IF(COUNTIF($Q7:$AF7,"?*")>0,", ","")&"incisos A-E","") | AH7: =IF(AND(OR($A7="Selección de la mejor respuesta",$A7="Subítem de caso o problema"),TRIM($I7)<>"",NOT(OR(LEFT(TRIM($I7),1)="A",LEFT(TRIM($I7),1)="B",LEFT(TRIM($I7),1)="C",LEFT(TRIM($I7),1)="D",LEFT(TRIM($I7),1)="E"))),IF(COUNTIF($Q7:$AG7,"?*")>0,", ","")&"respuesta A-E","") | AI7: =IF(AND(OR($A7="Ítems agrupados por caso clínico o problema",$A7="Opción de Emparejamiento Ampliado"),COUNTIF($D7:$H7,"?*")>0),IF(COUNTIF($Q7:$AH7,"?*")>0,", ","")&"sin incisos","") | AJ7: =IF(AND($A7="Emparejamiento Ampliado",COUNTIF($D7:$H7,"?*")<2),IF(COUNTIF($Q7:$AI7,"?*")>0,", ","")&"minimo 2 claves","") | AK7: =IF(AND($A7="Opción de Emparejamiento Ampliado",NOT(OR(LEFT(TRIM($I7),1)="A",LEFT(TRIM($I7),1)="B",LEFT(TRIM($I7),1)="C",LEFT(TRIM($I7),1)="D",LEFT(TRIM($I7),1)="E"))),IF(COUNTIF($Q7:$AJ7,"?*")>0,", ","")&"respuesta A-E","") | AL7: =IF(TRIM($K7)="",IF(COUNTIF($M7:$M7,"?*")>0,", ","")&"parcial","") | AM7: =IF(AND(TRIM($K7)<>"",TRIM($K7)<>VALIDACIONES!$G$1),IF(COUNTIF($M7:$N7,"?*")>0,", ","")&"parcial distinto a "&VALIDACIONES!$G$1,"") | AN7: =IF(AND(OR($A7="Ítems agrupados por caso clínico o problema",$A7="Subítem de caso o problema",$A7="Emparejamiento Ampliado",$A7="Opción de Emparejamiento Ampliado"),TRIM($B7)=""),IF(COUNTIF($M7:$O7,"?*")>0,", ","")&"grupo","")
D8: =IF($A8="Verdadero o Falso Simple","Verdadero",IF($A8="Respuesta A/B/Ambas/Ninguna","A. Si la primera es verdadera",IF($A8="Verdadero o Falso Complejas","1. ",""))) | E8: =IF($A8="Verdadero o Falso Simple","Falso",IF($A8="Respuesta A/B/Ambas/Ninguna","B. Si la segunda es verdadera",IF($A8="Verdadero o Falso Complejas","2. ",""))) | F8: =IF($A8="Respuesta A/B/Ambas/Ninguna","C. Si ambas son verdaderas",IF($A8="Verdadero o Falso Complejas","3. ","")) | G8: =IF($A8="Respuesta A/B/Ambas/Ninguna","D. Si ninguna es verdadera",IF($A8="Verdadero o Falso Complejas","4. ","")) | H8: =IF($A8="Verdadero o Falso Simple","",IF($A8="Respuesta A/B/Ambas/Ninguna","",IF($A8="Verdadero o Falso Complejas","",""))) | J8: 1 | K8: 2P | L8: =IF(TRIM($A8)="","",IF(OR($A8="Selección de la mejor respuesta",$A8="SELECCION_MEJOR_RESPUESTA",$A8="Subítem de caso o problema",$A8="SUBITEM_CASO"),IF(TRIM($C8)="","Completar enunciado",IF(SUMPRODUCT(--(LEN(TRIM($D8:$H8&""))>0))<5,"Completar opciones A-E",IF(AND(TRIM($I8)<>"",OR(LEFT(TRIM($I8),1)="A",LEFT(TRIM($I8),1)="B",LEFT(TRIM($I8),1)="C",LEFT(TRIM($I8),1)="D",LEFT(TRIM($I8),1)="E")),"OK","Completar respuesta correcta A-E"))),IF(TRIM($A8)="","",IF(COUNTIF($Q8:$AJ8,"?*")=0,"OK","Falta revisar: "&$Q8&$R8&$S8&$T8&$U8&$V8&$W8&$X8&$Y8&$Z8&$AA8&$AB8&$AC8&$AD8&$AE8&$AF8&$AG8&$AH8&$AI8&$AJ8)))) | Q8: =IF(TRIM($C8)="","enunciado","") | R8: =IF(TRIM($K8)="",IF(COUNTIF($Q8:$Q8,"?*")>0,", ","")&"parcial","") | S8: =IF(AND(TRIM($K8)<>"",TRIM($K8)<>VALIDACIONES!$G$1),IF(COUNTIF($Q8:$R8,"?*")>0,", ","")&"parcial distinto a "&VALIDACIONES!$G$1,"") | T8: =IF(AND(OR($A8="Ítems agrupados por caso clínico o problema",$A8="Subítem de caso o problema",$A8="Emparejamiento Ampliado",$A8="Opción de Emparejamiento Ampliado"),TRIM($B8)=""),IF(COUNTIF($Q8:$S8,"?*")>0,", ","")&"grupo","") | U8: =IF(AND(OR($A8="Verdadero o Falso Simple",$A8="Respuesta A/B/Ambas/Ninguna",$A8="Verdadero o Falso Complejas",$A8="Selección de la mejor respuesta",$A8="Subítem de caso o problema",$A8="Opción de Emparejamiento Ampliado"),TRIM($I8)=""),IF(COUNTIF($Q8:$T8,"?*")>0,", ","")&"respuesta_correcta","") | V8: =IF(AND(OR($A8="Verdadero o Falso Simple",$A8="Respuesta A/B/Ambas/Ninguna",$A8="Verdadero o Falso Complejas",$A8="Selección de la mejor respuesta",$A8="Subítem de caso o problema",$A8="Opción de Emparejamiento Ampliado"),TRIM($J8)=""),IF(COUNTIF($Q8:$U8,"?*")>0,", ","")&"dificultad","") | W8: =IF(AND(OR($A8="Ítems agrupados por caso clínico o problema",$A8="Emparejamiento Ampliado"),TRIM($I8)<>""),IF(COUNTIF($Q8:$V8,"?*")>0,", ","")&"respuesta debe ir vacia","") | X8: =IF(AND(OR($A8="Ítems agrupados por caso clínico o problema",$A8="Emparejamiento Ampliado"),TRIM($J8)<>""),IF(COUNTIF($Q8:$W8,"?*")>0,", ","")&"dificultad debe ir vacia","") | Y8: =IF(AND($A8="Verdadero o Falso Simple",OR(COUNTIF($D8:$E8,"?*")<2,COUNTIF($F8:$H8,"?*")>0)),IF(COUNTIF($Q8:$X8,"?*")>0,", ","")&"incisos A-B","") | Z8: =IF(AND($A8="Verdadero o Falso Simple",TRIM($I8)<>"",NOT(OR(LEFT(TRIM($I8),1)="A",LEFT(TRIM($I8),1)="B"))),IF(COUNTIF($Q8:$Y8,"?*")>0,", ","")&"respuesta A-B","") | AA8: =IF(AND($A8="Respuesta A/B/Ambas/Ninguna",COUNTIF($D8:$G8,"?*")<4),IF(COUNTIF($Q8:$Z8,"?*")>0,", ","")&"opciones A-D","") | AB8: =IF(AND($A8="Respuesta A/B/Ambas/Ninguna",COUNTIF($H8:$H8,"?*")>0),IF(COUNTIF($Q8:$AA8,"?*")>0,", ","")&"opcion E deshabilitada","") | AC8: =IF(AND($A8="Respuesta A/B/Ambas/Ninguna",TRIM($I8)<>"",NOT(OR(LEFT(TRIM($I8),1)="A",LEFT(TRIM($I8),1)="B",LEFT(TRIM($I8),1)="C",LEFT(TRIM($I8),1)="D"))),IF(COUNTIF($Q8:$AB8,"?*")>0,", ","")&"respuesta A-D","") | AD8: =IF(AND($A8="Verdadero o Falso Complejas",OR(LEN(TRIM(SUBSTITUTE($D8,"1.","")))=0,LEN(TRIM(SUBSTITUTE($E8,"2.","")))=0,LEN(TRIM(SUBSTITUTE($F8,"3.","")))=0,LEN(TRIM(SUBSTITUTE($G8,"4.","")))=0)),IF(COUNTIF($Q8:$AC8,"?*")>0,", ","")&"incisos 1-4","") | AE8: =IF(AND($A8="Verdadero o Falso Complejas",COUNTIF($H8:$H8,"?*")>0),IF(COUNTIF($Q8:$AD8,"?*")>0,", ","")&"opcion E deshabilitada","") | AF8: =IF(AND($A8="Verdadero o Falso Complejas",TRIM($I8)<>"",NOT(OR(LEFT(TRIM($I8),1)="A",LEFT(TRIM($I8),1)="B",LEFT(TRIM($I8),1)="C",LEFT(TRIM($I8),1)="D",LEFT(TRIM($I8),1)="E"))),IF(COUNTIF($Q8:$AE8,"?*")>0,", ","")&"respuesta A-E","") | AG8: =IF(AND(OR($A8="Selección de la mejor respuesta",$A8="Subítem de caso o problema"),COUNTA($D8:$H8)<5),IF(COUNTIF($Q8:$AF8,"?*")>0,", ","")&"incisos A-E","") | AH8: =IF(AND(OR($A8="Selección de la mejor respuesta",$A8="Subítem de caso o problema"),TRIM($I8)<>"",NOT(OR(LEFT(TRIM($I8),1)="A",LEFT(TRIM($I8),1)="B",LEFT(TRIM($I8),1)="C",LEFT(TRIM($I8),1)="D",LEFT(TRIM($I8),1)="E"))),IF(COUNTIF($Q8:$AG8,"?*")>0,", ","")&"respuesta A-E","") | AI8: =IF(AND(OR($A8="Ítems agrupados por caso clínico o problema",$A8="Opción de Emparejamiento Ampliado"),COUNTIF($D8:$H8,"?*")>0),IF(COUNTIF($Q8:$AH8,"?*")>0,", ","")&"sin incisos","") | AJ8: =IF(AND($A8="Emparejamiento Ampliado",COUNTIF($D8:$H8,"?*")<2),IF(COUNTIF($Q8:$AI8,"?*")>0,", ","")&"minimo 2 claves","") | AK8: =IF(AND($A8="Opción de Emparejamiento Ampliado",NOT(OR(LEFT(TRIM($I8),1)="A",LEFT(TRIM($I8),1)="B",LEFT(TRIM($I8),1)="C",LEFT(TRIM($I8),1)="D",LEFT(TRIM($I8),1)="E"))),IF(COUNTIF($Q8:$AJ8,"?*")>0,", ","")&"respuesta A-E","") | AL8: =IF(TRIM($K8)="",IF(COUNTIF($M8:$M8,"?*")>0,", ","")&"parcial","") | AM8: =IF(AND(TRIM($K8)<>"",TRIM($K8)<>VALIDACIONES!$G$1),IF(COUNTIF($M8:$N8,"?*")>0,", ","")&"parcial distinto a "&VALIDACIONES!$G$1,"") | AN8: =IF(AND(OR($A8="Ítems agrupados por caso clínico o problema",$A8="Subítem de caso o problema",$A8="Emparejamiento Ampliado",$A8="Opción de Emparejamiento Ampliado"),TRIM($B8)=""),IF(COUNTIF($M8:$O8,"?*")>0,", ","")&"grupo","") | AO8: CUOTAS POR GRUPO TIPOLÓGICO
D9: =IF($A9="Verdadero o Falso Simple","Verdadero",IF($A9="Respuesta A/B/Ambas/Ninguna","A. Si la primera es verdadera",IF($A9="Verdadero o Falso Complejas","1. ",""))) | E9: =IF($A9="Verdadero o Falso Simple","Falso",IF($A9="Respuesta A/B/Ambas/Ninguna","B. Si la segunda es verdadera",IF($A9="Verdadero o Falso Complejas","2. ",""))) | F9: =IF($A9="Respuesta A/B/Ambas/Ninguna","C. Si ambas son verdaderas",IF($A9="Verdadero o Falso Complejas","3. ","")) | G9: =IF($A9="Respuesta A/B/Ambas/Ninguna","D. Si ninguna es verdadera",IF($A9="Verdadero o Falso Complejas","4. ","")) | H9: =IF($A9="Verdadero o Falso Simple","",IF($A9="Respuesta A/B/Ambas/Ninguna","",IF($A9="Verdadero o Falso Complejas","",""))) | J9: 1 | K9: 2P | L9: =IF(TRIM($A9)="","",IF(OR($A9="Selección de la mejor respuesta",$A9="SELECCION_MEJOR_RESPUESTA",$A9="Subítem de caso o problema",$A9="SUBITEM_CASO"),IF(TRIM($C9)="","Completar enunciado",IF(SUMPRODUCT(--(LEN(TRIM($D9:$H9&""))>0))<5,"Completar opciones A-E",IF(AND(TRIM($I9)<>"",OR(LEFT(TRIM($I9),1)="A",LEFT(TRIM($I9),1)="B",LEFT(TRIM($I9),1)="C",LEFT(TRIM($I9),1)="D",LEFT(TRIM($I9),1)="E")),"OK","Completar respuesta correcta A-E"))),IF(TRIM($A9)="","",IF(COUNTIF($Q9:$AJ9,"?*")=0,"OK","Falta revisar: "&$Q9&$R9&$S9&$T9&$U9&$V9&$W9&$X9&$Y9&$Z9&$AA9&$AB9&$AC9&$AD9&$AE9&$AF9&$AG9&$AH9&$AI9&$AJ9)))) | Q9: =IF(TRIM($C9)="","enunciado","") | R9: =IF(TRIM($K9)="",IF(COUNTIF($Q9:$Q9,"?*")>0,", ","")&"parcial","") | S9: =IF(AND(TRIM($K9)<>"",TRIM($K9)<>VALIDACIONES!$G$1),IF(COUNTIF($Q9:$R9,"?*")>0,", ","")&"parcial distinto a "&VALIDACIONES!$G$1,"") | T9: =IF(AND(OR($A9="Ítems agrupados por caso clínico o problema",$A9="Subítem de caso o problema",$A9="Emparejamiento Ampliado",$A9="Opción de Emparejamiento Ampliado"),TRIM($B9)=""),IF(COUNTIF($Q9:$S9,"?*")>0,", ","")&"grupo","") | U9: =IF(AND(OR($A9="Verdadero o Falso Simple",$A9="Respuesta A/B/Ambas/Ninguna",$A9="Verdadero o Falso Complejas",$A9="Selección de la mejor respuesta",$A9="Subítem de caso o problema",$A9="Opción de Emparejamiento Ampliado"),TRIM($I9)=""),IF(COUNTIF($Q9:$T9,"?*")>0,", ","")&"respuesta_correcta","") | V9: =IF(AND(OR($A9="Verdadero o Falso Simple",$A9="Respuesta A/B/Ambas/Ninguna",$A9="Verdadero o Falso Complejas",$A9="Selección de la mejor respuesta",$A9="Subítem de caso o problema",$A9="Opción de Emparejamiento Ampliado"),TRIM($J9)=""),IF(COUNTIF($Q9:$U9,"?*")>0,", ","")&"dificultad","") | W9: =IF(AND(OR($A9="Ítems agrupados por caso clínico o problema",$A9="Emparejamiento Ampliado"),TRIM($I9)<>""),IF(COUNTIF($Q9:$V9,"?*")>0,", ","")&"respuesta debe ir vacia","") | X9: =IF(AND(OR($A9="Ítems agrupados por caso clínico o problema",$A9="Emparejamiento Ampliado"),TRIM($J9)<>""),IF(COUNTIF($Q9:$W9,"?*")>0,", ","")&"dificultad debe ir vacia","") | Y9: =IF(AND($A9="Verdadero o Falso Simple",OR(COUNTIF($D9:$E9,"?*")<2,COUNTIF($F9:$H9,"?*")>0)),IF(COUNTIF($Q9:$X9,"?*")>0,", ","")&"incisos A-B","") | Z9: =IF(AND($A9="Verdadero o Falso Simple",TRIM($I9)<>"",NOT(OR(LEFT(TRIM($I9),1)="A",LEFT(TRIM($I9),1)="B"))),IF(COUNTIF($Q9:$Y9,"?*")>0,", ","")&"respuesta A-B","") | AA9: =IF(AND($A9="Respuesta A/B/Ambas/Ninguna",COUNTIF($D9:$G9,"?*")<4),IF(COUNTIF($Q9:$Z9,"?*")>0,", ","")&"opciones A-D","") | AB9: =IF(AND($A9="Respuesta A/B/Ambas/Ninguna",COUNTIF($H9:$H9,"?*")>0),IF(COUNTIF($Q9:$AA9,"?*")>0,", ","")&"opcion E deshabilitada","") | AC9: =IF(AND($A9="Respuesta A/B/Ambas/Ninguna",TRIM($I9)<>"",NOT(OR(LEFT(TRIM($I9),1)="A",LEFT(TRIM($I9),1)="B",LEFT(TRIM($I9),1)="C",LEFT(TRIM($I9),1)="D"))),IF(COUNTIF($Q9:$AB9,"?*")>0,", ","")&"respuesta A-D","") | AD9: =IF(AND($A9="Verdadero o Falso Complejas",OR(LEN(TRIM(SUBSTITUTE($D9,"1.","")))=0,LEN(TRIM(SUBSTITUTE($E9,"2.","")))=0,LEN(TRIM(SUBSTITUTE($F9,"3.","")))=0,LEN(TRIM(SUBSTITUTE($G9,"4.","")))=0)),IF(COUNTIF($Q9:$AC9,"?*")>0,", ","")&"incisos 1-4","") | AE9: =IF(AND($A9="Verdadero o Falso Complejas",COUNTIF($H9:$H9,"?*")>0),IF(COUNTIF($Q9:$AD9,"?*")>0,", ","")&"opcion E deshabilitada","") | AF9: =IF(AND($A9="Verdadero o Falso Complejas",TRIM($I9)<>"",NOT(OR(LEFT(TRIM($I9),1)="A",LEFT(TRIM($I9),1)="B",LEFT(TRIM($I9),1)="C",LEFT(TRIM($I9),1)="D",LEFT(TRIM($I9),1)="E"))),IF(COUNTIF($Q9:$AE9,"?*")>0,", ","")&"respuesta A-E","") | AG9: =IF(AND(OR($A9="Selección de la mejor respuesta",$A9="Subítem de caso o problema"),COUNTA($D9:$H9)<5),IF(COUNTIF($Q9:$AF9,"?*")>0,", ","")&"incisos A-E","") | AH9: =IF(AND(OR($A9="Selección de la mejor respuesta",$A9="Subítem de caso o problema"),TRIM($I9)<>"",NOT(OR(LEFT(TRIM($I9),1)="A",LEFT(TRIM($I9),1)="B",LEFT(TRIM($I9),1)="C",LEFT(TRIM($I9),1)="D",LEFT(TRIM($I9),1)="E"))),IF(COUNTIF($Q9:$AG9,"?*")>0,", ","")&"respuesta A-E","") | AI9: =IF(AND(OR($A9="Ítems agrupados por caso clínico o problema",$A9="Opción de Emparejamiento Ampliado"),COUNTIF($D9:$H9,"?*")>0),IF(COUNTIF($Q9:$AH9,"?*")>0,", ","")&"sin incisos","") | AJ9: =IF(AND($A9="Emparejamiento Ampliado",COUNTIF($D9:$H9,"?*")<2),IF(COUNTIF($Q9:$AI9,"?*")>0,", ","")&"minimo 2 claves","") | AK9: =IF(AND($A9="Opción de Emparejamiento Ampliado",NOT(OR(LEFT(TRIM($I9),1)="A",LEFT(TRIM($I9),1)="B",LEFT(TRIM($I9),1)="C",LEFT(TRIM($I9),1)="D",LEFT(TRIM($I9),1)="E"))),IF(COUNTIF($Q9:$AJ9,"?*")>0,", ","")&"respuesta A-E","") | AL9: =IF(TRIM($K9)="",IF(COUNTIF($M9:$M9,"?*")>0,", ","")&"parcial","") | AM9: =IF(AND(TRIM($K9)<>"",TRIM($K9)<>VALIDACIONES!$G$1),IF(COUNTIF($M9:$N9,"?*")>0,", ","")&"parcial distinto a "&VALIDACIONES!$G$1,"") | AN9: =IF(AND(OR($A9="Ítems agrupados por caso clínico o problema",$A9="Subítem de caso o problema",$A9="Emparejamiento Ampliado",$A9="Opción de Emparejamiento Ampliado"),TRIM($B9)=""),IF(COUNTIF($M9:$O9,"?*")>0,", ","")&"grupo","") | AO9: Grupo 1 (V/F y Premisas) | AP9: =COUNTIF($A$2:$A$1001,VALIDACIONES!$A$1)+COUNTIF($A$2:$A$1001,VALIDACIONES!$A$2)+COUNTIF($A$2:$A$1001,VALIDACIONES!$A$3)+COUNTIF($A$2:$A$1001,"VERDADERO_O_FALSO_SIMPLE")+COUNTIF($A$2:$A$1001,"VERDADERO_O_FALSO_COMPLEJAS")+COUNTIF($A$2:$A$1001,"RESPUESTA_PREMISAS_ABCD")+COUNTIF($A$2:$A$1001,"FALSO_VERDADERO")+COUNTIF($A$2:$A$1001,"PREGUNTA_CON_CLAVE")+COUNTIF($A$2:$A$1001,"RESPUESTA_COMPUESTA") | AQ9: Meta: 15
D10: =IF($A10="Verdadero o Falso Simple","Verdadero",IF($A10="Respuesta A/B/Ambas/Ninguna","A. Si la primera es verdadera",IF($A10="Verdadero o Falso Complejas","1. ",""))) | E10: =IF($A10="Verdadero o Falso Simple","Falso",IF($A10="Respuesta A/B/Ambas/Ninguna","B. Si la segunda es verdadera",IF($A10="Verdadero o Falso Complejas","2. ",""))) | F10: =IF($A10="Respuesta A/B/Ambas/Ninguna","C. Si ambas son verdaderas",IF($A10="Verdadero o Falso Complejas","3. ","")) | G10: =IF($A10="Respuesta A/B/Ambas/Ninguna","D. Si ninguna es verdadera",IF($A10="Verdadero o Falso Complejas","4. ","")) | H10: =IF($A10="Verdadero o Falso Simple","",IF($A10="Respuesta A/B/Ambas/Ninguna","",IF($A10="Verdadero o Falso Complejas","",""))) | J10: 1 | K10: 2P | L10: =IF(TRIM($A10)="","",IF(OR($A10="Selección de la mejor respuesta",$A10="SELECCION_MEJOR_RESPUESTA",$A10="Subítem de caso o problema",$A10="SUBITEM_CASO"),IF(TRIM($C10)="","Completar enunciado",IF(SUMPRODUCT(--(LEN(TRIM($D10:$H10&""))>0))<5,"Completar opciones A-E",IF(AND(TRIM($I10)<>"",OR(LEFT(TRIM($I10),1)="A",LEFT(TRIM($I10),1)="B",LEFT(TRIM($I10),1)="C",LEFT(TRIM($I10),1)="D",LEFT(TRIM($I10),1)="E")),"OK","Completar respuesta correcta A-E"))),IF(TRIM($A10)="","",IF(COUNTIF($Q10:$AJ10,"?*")=0,"OK","Falta revisar: "&$Q10&$R10&$S10&$T10&$U10&$V10&$W10&$X10&$Y10&$Z10&$AA10&$AB10&$AC10&$AD10&$AE10&$AF10&$AG10&$AH10&$AI10&$AJ10)))) | Q10: =IF(TRIM($C10)="","enunciado","") | R10: =IF(TRIM($K10)="",IF(COUNTIF($Q10:$Q10,"?*")>0,", ","")&"parcial","") | S10: =IF(AND(TRIM($K10)<>"",TRIM($K10)<>VALIDACIONES!$G$1),IF(COUNTIF($Q10:$R10,"?*")>0,", ","")&"parcial distinto a "&VALIDACIONES!$G$1,"") | T10: =IF(AND(OR($A10="Ítems agrupados por caso clínico o problema",$A10="Subítem de caso o problema",$A10="Emparejamiento Ampliado",$A10="Opción de Emparejamiento Ampliado"),TRIM($B10)=""),IF(COUNTIF($Q10:$S10,"?*")>0,", ","")&"grupo","") | U10: =IF(AND(OR($A10="Verdadero o Falso Simple",$A10="Respuesta A/B/Ambas/Ninguna",$A10="Verdadero o Falso Complejas",$A10="Selección de la mejor respuesta",$A10="Subítem de caso o problema",$A10="Opción de Emparejamiento Ampliado"),TRIM($I10)=""),IF(COUNTIF($Q10:$T10,"?*")>0,", ","")&"respuesta_correcta","") | V10: =IF(AND(OR($A10="Verdadero o Falso Simple",$A10="Respuesta A/B/Ambas/Ninguna",$A10="Verdadero o Falso Complejas",$A10="Selección de la mejor respuesta",$A10="Subítem de caso o problema",$A10="Opción de Emparejamiento Ampliado"),TRIM($J10)=""),IF(COUNTIF($Q10:$U10,"?*")>0,", ","")&"dificultad","") | W10: =IF(AND(OR($A10="Ítems agrupados por caso clínico o problema",$A10="Emparejamiento Ampliado"),TRIM($I10)<>""),IF(COUNTIF($Q10:$V10,"?*")>0,", ","")&"respuesta debe ir vacia","") | X10: =IF(AND(OR($A10="Ítems agrupados por caso clínico o problema",$A10="Emparejamiento Ampliado"),TRIM($J10)<>""),IF(COUNTIF($Q10:$W10,"?*")>0,", ","")&"dificultad debe ir vacia","") | Y10: =IF(AND($A10="Verdadero o Falso Simple",OR(COUNTIF($D10:$E10,"?*")<2,COUNTIF($F10:$H10,"?*")>0)),IF(COUNTIF($Q10:$X10,"?*")>0,", ","")&"incisos A-B","") | Z10: =IF(AND($A10="Verdadero o Falso Simple",TRIM($I10)<>"",NOT(OR(LEFT(TRIM($I10),1)="A",LEFT(TRIM($I10),1)="B"))),IF(COUNTIF($Q10:$Y10,"?*")>0,", ","")&"respuesta A-B","") | AA10: =IF(AND($A10="Respuesta A/B/Ambas/Ninguna",COUNTIF($D10:$G10,"?*")<4),IF(COUNTIF($Q10:$Z10,"?*")>0,", ","")&"opciones A-D","") | AB10: =IF(AND($A10="Respuesta A/B/Ambas/Ninguna",COUNTIF($H10:$H10,"?*")>0),IF(COUNTIF($Q10:$AA10,"?*")>0,", ","")&"opcion E deshabilitada","") | AC10: =IF(AND($A10="Respuesta A/B/Ambas/Ninguna",TRIM($I10)<>"",NOT(OR(LEFT(TRIM($I10),1)="A",LEFT(TRIM($I10),1)="B",LEFT(TRIM($I10),1)="C",LEFT(TRIM($I10),1)="D"))),IF(COUNTIF($Q10:$AB10,"?*")>0,", ","")&"respuesta A-D","") | AD10: =IF(AND($A10="Verdadero o Falso Complejas",OR(LEN(TRIM(SUBSTITUTE($D10,"1.","")))=0,LEN(TRIM(SUBSTITUTE($E10,"2.","")))=0,LEN(TRIM(SUBSTITUTE($F10,"3.","")))=0,LEN(TRIM(SUBSTITUTE($G10,"4.","")))=0)),IF(COUNTIF($Q10:$AC10,"?*")>0,", ","")&"incisos 1-4","") | AE10: =IF(AND($A10="Verdadero o Falso Complejas",COUNTIF($H10:$H10,"?*")>0),IF(COUNTIF($Q10:$AD10,"?*")>0,", ","")&"opcion E deshabilitada","") | AF10: =IF(AND($A10="Verdadero o Falso Complejas",TRIM($I10)<>"",NOT(OR(LEFT(TRIM($I10),1)="A",LEFT(TRIM($I10),1)="B",LEFT(TRIM($I10),1)="C",LEFT(TRIM($I10),1)="D",LEFT(TRIM($I10),1)="E"))),IF(COUNTIF($Q10:$AE10,"?*")>0,", ","")&"respuesta A-E","") | AG10: =IF(AND(OR($A10="Selección de la mejor respuesta",$A10="Subítem de caso o problema"),COUNTA($D10:$H10)<5),IF(COUNTIF($Q10:$AF10,"?*")>0,", ","")&"incisos A-E","") | AH10: =IF(AND(OR($A10="Selección de la mejor respuesta",$A10="Subítem de caso o problema"),TRIM($I10)<>"",NOT(OR(LEFT(TRIM($I10),1)="A",LEFT(TRIM($I10),1)="B",LEFT(TRIM($I10),1)="C",LEFT(TRIM($I10),1)="D",LEFT(TRIM($I10),1)="E"))),IF(COUNTIF($Q10:$AG10,"?*")>0,", ","")&"respuesta A-E","") | AI10: =IF(AND(OR($A10="Ítems agrupados por caso clínico o problema",$A10="Opción de Emparejamiento Ampliado"),COUNTIF($D10:$H10,"?*")>0),IF(COUNTIF($Q10:$AH10,"?*")>0,", ","")&"sin incisos","") | AJ10: =IF(AND($A10="Emparejamiento Ampliado",COUNTIF($D10:$H10,"?*")<2),IF(COUNTIF($Q10:$AI10,"?*")>0,", ","")&"minimo 2 claves","") | AK10: =IF(AND($A10="Opción de Emparejamiento Ampliado",NOT(OR(LEFT(TRIM($I10),1)="A",LEFT(TRIM($I10),1)="B",LEFT(TRIM($I10),1)="C",LEFT(TRIM($I10),1)="D",LEFT(TRIM($I10),1)="E"))),IF(COUNTIF($Q10:$AJ10,"?*")>0,", ","")&"respuesta A-E","") | AL10: =IF(TRIM($K10)="",IF(COUNTIF($M10:$M10,"?*")>0,", ","")&"parcial","") | AM10: =IF(AND(TRIM($K10)<>"",TRIM($K10)<>VALIDACIONES!$G$1),IF(COUNTIF($M10:$N10,"?*")>0,", ","")&"parcial distinto a "&VALIDACIONES!$G$1,"") | AN10: =IF(AND(OR($A10="Ítems agrupados por caso clínico o problema",$A10="Subítem de caso o problema",$A10="Emparejamiento Ampliado",$A10="Opción de Emparejamiento Ampliado"),TRIM($B10)=""),IF(COUNTIF($M10:$O10,"?*")>0,", ","")&"grupo","") | AO10: Grupo 2 (Mejor Respuesta) | AP10: =COUNTIF($A$2:$A$1001,VALIDACIONES!$A$4)+COUNTIF($A$2:$A$1001,"SELECCION_MEJOR_RESPUESTA")+COUNTIF($A$2:$A$1001,"SELECCION_SIMPLE")+COUNTIF($A$2:$A$1001,"SELECCION_UNICA") | AQ10: Meta: 30
